<?xml version='1.0'?>

<robot name="mybot" xmlns:xacro="http://www.ros.org/wiki/xacro">

	<xacro:property name="wheel_radius" value="0.1"/>
	<xacro:property name="wheel_length" value="0.05"/>

	<xacro:macro name="chasis_wheel" params="name wheel_origin_angle *shape">
	<!--xacro:property name="wheel_origin_angle" value="0 1.5707 1.5707"/-->
	<link name="${name}_wheel">
	<visual>
		<origin xyz="0 0 0" rpy="${wheel_origin_angle}"/>
		<geometry>
			<xacro:insert_block name="shape" />
		</geometry>
		<material name="blue"/>
	</visual>
	<collision>
		<origin xyz="0 0 0" rpy="${wheel_origin_angle}"/>
		<geometry>
			<xacro:insert_block name="shape" />
		</geometry>
	</collision>
	<xacro:default_inertial mass="5"/>

	</link>
	</xacro:macro>


	<xacro:macro name="sphere_wheel" params="name">
	<link name="${name}_wheel">
	<collision>
      	  <origin xyz="0 0 0" rpy=" 0 0 0"/>
      	  <geometry>
            <sphere radius="0.03"/>
      	  </geometry>
      	  <surface>
            <friction>
              <ode>
                <mu>0.1</mu>
                <mu2>.1</mu2>
                <slip1>0.99</slip1>
                <slip2>0.99</slip2>
              </ode>
             </friction>
     	  </surface>
    	</collision>
    	<visual>
	    <origin xyz="0 0 0" rpy=" 0 0 0"/>
          <geometry>
            <sphere radius="0.03"/>
          </geometry>
        </visual>
	<xacro:default_inertial mass="1"/>

	</link>
	</xacro:macro>


	<xacro:chasis_wheel name="left" wheel_origin_angle="0 1.5707 1.5707">
		<cylinder radius="${wheel_radius}" length="${wheel_length}"/>
	</xacro:chasis_wheel>
	<xacro:chasis_wheel name="right" wheel_origin_angle="0 1.5707 1.5707">
		<cylinder radius="${wheel_radius}" length="${wheel_length}"/>
	</xacro:chasis_wheel>

	<joint type="continuous" name="left_wheel_hinge">
	<origin xyz="0 0.15 0" rpy="0 0 0"/>
	<!--origin xyz="0.1 0.13 0" rpy="0 1.5707 1.5707"/-->
	<child link="left_wheel"/>
	<parent link="chassis"/>
	<axis xyz="0 1 0" rpy="0 0 0"/>
	<limit effort="100" velocity="100"/>
	<joint_properties damping="0.0" friction="0.0"/>
	</joint>

	<joint type="continuous" name="right_wheel_hinge">
	<origin xyz="0 -0.15 0" rpy="0 0 0"/>
	<!--origin xyz="0.1 -0.13 0" rpy="0 1.5707 1.5707"/-->
	<child link="right_wheel"/>
	<parent link="chassis"/>
	<axis xyz="0 1 0" rpy="0 0 0"/>
	<limit effort="100" velocity="100"/>
	<joint_properties damping="0.0" friction="0.0"/>
	</joint>
</robot>
